Traceback (most recent call last):
  File "C:\Users\henry\miniconda3\envs\ml_venv\lib\site-packages\jupyter_cache\executors\utils.py", line 58, in single_nb_execution
    executenb(
  File "C:\Users\henry\miniconda3\envs\ml_venv\lib\site-packages\nbclient\client.py", line 1319, in execute
    return NotebookClient(nb=nb, resources=resources, km=km, **kwargs).execute()
  File "C:\Users\henry\miniconda3\envs\ml_venv\lib\site-packages\jupyter_core\utils\__init__.py", line 165, in wrapped
    return loop.run_until_complete(inner)
  File "C:\Users\henry\miniconda3\envs\ml_venv\lib\asyncio\base_events.py", line 647, in run_until_complete
    return future.result()
  File "C:\Users\henry\miniconda3\envs\ml_venv\lib\site-packages\nbclient\client.py", line 709, in async_execute
    await self.async_execute_cell(
  File "C:\Users\henry\miniconda3\envs\ml_venv\lib\site-packages\nbclient\client.py", line 1062, in async_execute_cell
    await self._check_raise_for_error(cell, cell_index, exec_reply)
  File "C:\Users\henry\miniconda3\envs\ml_venv\lib\site-packages\nbclient\client.py", line 918, in _check_raise_for_error
    raise CellExecutionError.from_cell_and_msg(cell, exec_reply_content)
nbclient.exceptions.CellExecutionError: An error occurred while executing the following cell:
------------------
df, meta = pyreadstat.read_sav("/Users/juansebastianquintanacontreras/Desktop/Proyecto_seminario/CACU1985A2019.sav")
print(df.head())  # Ver las primeras filas del DataFrame
------------------


[1;31m---------------------------------------------------------------------------[0m
[1;31mPyreadstatError[0m                           Traceback (most recent call last)
Cell [1;32mIn[2], line 1[0m
[1;32m----> 1[0m df, meta [38;5;241m=[39m [43mpyreadstat[49m[38;5;241;43m.[39;49m[43mread_sav[49m[43m([49m[38;5;124;43m"[39;49m[38;5;124;43m/Users/juansebastianquintanacontreras/Desktop/Proyecto_seminario/CACU1985A2019.sav[39;49m[38;5;124;43m"[39;49m[43m)[49m
[0;32m      2[0m [38;5;28mprint[39m(df[38;5;241m.[39mhead())  [38;5;66;03m# Ver las primeras filas del DataFrame[39;00m

File [1;32mpyreadstat\\pyreadstat.pyx:389[0m, in [0;36mpyreadstat.pyreadstat.read_sav[1;34m()[0m

File [1;32mpyreadstat\\_readstat_parser.pyx:1104[0m, in [0;36mpyreadstat._readstat_parser.run_conversion[1;34m()[0m

[1;31mPyreadstatError[0m: File /Users/juansebastianquintanacontreras/Desktop/Proyecto_seminario/CACU1985A2019.sav does not exist!

